Unable to init server: Could not connect: Connection refused
Unable to init server: 연결할 수 없습니다: Connection refused

(droppcl_swarm_driver.py:24384): Gdk-CRITICAL **: 20:00:44.310: gdk_cursor_new_for_display: assertion 'GDK_IS_DISPLAY (display)' failed
Traceback (most recent call last):
  File "droppcl_swarm_driver.py", line 313, in <module>
    main()
  File "droppcl_swarm_driver.py", line 156, in main
    log_callback
  File "/home/seth/projects/fed-learn-experiment/swarm/droppcl_swarm.py", line 108, in __init__
    self.enc_df = pd.read_csv(self._config['encounter-data-file'])
  File "/home/seth/.local/lib/python3.6/site-packages/pandas/io/parsers.py", line 676, in parser_f
    return _read(filepath_or_buffer, kwds)
  File "/home/seth/.local/lib/python3.6/site-packages/pandas/io/parsers.py", line 448, in _read
    parser = TextFileReader(fp_or_buf, **kwds)
  File "/home/seth/.local/lib/python3.6/site-packages/pandas/io/parsers.py", line 880, in __init__
    self._make_engine(self.engine)
  File "/home/seth/.local/lib/python3.6/site-packages/pandas/io/parsers.py", line 1114, in _make_engine
    self._engine = CParserWrapper(self.f, **self.options)
  File "/home/seth/.local/lib/python3.6/site-packages/pandas/io/parsers.py", line 1891, in __init__
    self._reader = parsers.TextReader(src, **kwds)
  File "pandas/_libs/parsers.pyx", line 529, in pandas._libs.parsers.TextReader.__cinit__
  File "pandas/_libs/parsers.pyx", line 749, in pandas._libs.parsers.TextReader._get_header
UnicodeDecodeError: 'utf-8' codec can't decode byte 0x80 in position 0: invalid start byte
